2023-03-09 11:17:21,803:ERROR:Execution.execute:Issue in Placing Order
Traceback (most recent call last):
  File "C:\Users\niraj.munot\Desktop\Codes\Execution_Fast\Execution\execute.py", line 126, in placeorder
    orderid = self.jf.placeorder(token, segment, ordertype, transactiontype, qty, price, producttype)
  File "C:\Users\niraj.munot\Desktop\Codes\Execution_Fast\Jiffy\jiffy.py", line 123, in placeorder
    return self._request("POST", endpoints['placeorder'], body)
  File "C:\Users\niraj.munot\Desktop\Codes\Execution_Fast\Jiffy\jiffy.py", line 183, in _request
    raise e
  File "C:\Users\niraj.munot\Desktop\Codes\Execution_Fast\Jiffy\jiffy.py", line 172, in _request
    raise requests.HTTPError(resp.text)
requests.exceptions.HTTPError: "Unauthorized, Session Expired or does'nt exists"
2023-03-09 11:17:21,821:ERROR:Execution.execute:Issue in Placing Order
Traceback (most recent call last):
  File "C:\Users\niraj.munot\Desktop\Codes\Execution_Fast\Execution\execute.py", line 126, in placeorder
    orderid = self.jf.placeorder(token, segment, ordertype, transactiontype, qty, price, producttype)
  File "C:\Users\niraj.munot\Desktop\Codes\Execution_Fast\Jiffy\jiffy.py", line 123, in placeorder
    return self._request("POST", endpoints['placeorder'], body)
  File "C:\Users\niraj.munot\Desktop\Codes\Execution_Fast\Jiffy\jiffy.py", line 183, in _request
    raise e
  File "C:\Users\niraj.munot\Desktop\Codes\Execution_Fast\Jiffy\jiffy.py", line 172, in _request
    raise requests.HTTPError(resp.text)
requests.exceptions.HTTPError: "Unauthorized, Session Expired or does'nt exists"
2023-03-09 11:17:21,829:ERROR:Execution.execute:Issue in Placing Order
Traceback (most recent call last):
  File "C:\Users\niraj.munot\Desktop\Codes\Execution_Fast\Execution\execute.py", line 126, in placeorder
    orderid = self.jf.placeorder(token, segment, ordertype, transactiontype, qty, price, producttype)
  File "C:\Users\niraj.munot\Desktop\Codes\Execution_Fast\Jiffy\jiffy.py", line 123, in placeorder
    return self._request("POST", endpoints['placeorder'], body)
  File "C:\Users\niraj.munot\Desktop\Codes\Execution_Fast\Jiffy\jiffy.py", line 183, in _request
    raise e
  File "C:\Users\niraj.munot\Desktop\Codes\Execution_Fast\Jiffy\jiffy.py", line 172, in _request
    raise requests.HTTPError(resp.text)
requests.exceptions.HTTPError: "Unauthorized, Session Expired or does'nt exists"
2023-03-09 11:17:22,514:ERROR:Execution.execute:Error in Orderplacement in singleorder Orderid not generated for orderdetails : {'reftag': 902, 'price': 38.15, 'token': 46024, 'qty': 25, 'strategyname': 'test_NF', 'transactiontype': 'sell', 'exchange': 'NSEFO'}
2023-03-09 11:17:22,526:ERROR:Execution.execute:Error in Orderplacement in singleorder Orderid not generated for orderdetails : {'reftag': 902, 'price': 38.15, 'token': 46024, 'qty': 25, 'strategyname': 'test_NF', 'transactiontype': 'sell', 'exchange': 'NSEFO'}
2023-03-09 11:17:22,555:ERROR:Execution.execute:Error in Orderplacement in singleorder Orderid not generated for orderdetails : {'reftag': 902, 'price': 38.15, 'token': 46024, 'qty': 25, 'strategyname': 'test_NF', 'transactiontype': 'sell', 'exchange': 'NSEFO'}
2023-03-09 11:24:07,395:ERROR:Execution.execute:Issue in Placing Order
Traceback (most recent call last):
  File "C:\Users\niraj.munot\Desktop\Codes\Execution_Fast\Execution\execute.py", line 126, in placeorder
    orderid = self.jf.placeorder(token, segment, ordertype, transactiontype, qty, price, producttype)
  File "C:\Users\niraj.munot\Desktop\Codes\Execution_Fast\Jiffy\jiffy.py", line 123, in placeorder
    return self._request("POST", endpoints['placeorder'], body)
  File "C:\Users\niraj.munot\Desktop\Codes\Execution_Fast\Jiffy\jiffy.py", line 183, in _request
    raise e
  File "C:\Users\niraj.munot\Desktop\Codes\Execution_Fast\Jiffy\jiffy.py", line 172, in _request
    raise requests.HTTPError(resp.text)
requests.exceptions.HTTPError: "Unauthorized, Session Expired or does'nt exists"
2023-03-09 11:24:07,396:ERROR:Execution.execute:Error in Orderplacement in singleorder Orderid not generated for orderdetails : {'reftag': 903, 'price': 38.15, 'token': 46024, 'qty': 25, 'strategyname': 'test_NF', 'transactiontype': 'sell', 'exchange': 'NSEFO'}
2023-03-09 11:24:07,412:ERROR:Execution.execute:Issue in Placing Order
Traceback (most recent call last):
  File "C:\Users\niraj.munot\Desktop\Codes\Execution_Fast\Execution\execute.py", line 126, in placeorder
    orderid = self.jf.placeorder(token, segment, ordertype, transactiontype, qty, price, producttype)
  File "C:\Users\niraj.munot\Desktop\Codes\Execution_Fast\Jiffy\jiffy.py", line 123, in placeorder
    return self._request("POST", endpoints['placeorder'], body)
  File "C:\Users\niraj.munot\Desktop\Codes\Execution_Fast\Jiffy\jiffy.py", line 183, in _request
    raise e
  File "C:\Users\niraj.munot\Desktop\Codes\Execution_Fast\Jiffy\jiffy.py", line 172, in _request
    raise requests.HTTPError(resp.text)
requests.exceptions.HTTPError: "Unauthorized, Session Expired or does'nt exists"
2023-03-09 11:24:07,412:ERROR:Execution.execute:Issue in Placing Order
Traceback (most recent call last):
  File "C:\Users\niraj.munot\Desktop\Codes\Execution_Fast\Execution\execute.py", line 126, in placeorder
    orderid = self.jf.placeorder(token, segment, ordertype, transactiontype, qty, price, producttype)
  File "C:\Users\niraj.munot\Desktop\Codes\Execution_Fast\Jiffy\jiffy.py", line 123, in placeorder
    return self._request("POST", endpoints['placeorder'], body)
  File "C:\Users\niraj.munot\Desktop\Codes\Execution_Fast\Jiffy\jiffy.py", line 183, in _request
    raise e
  File "C:\Users\niraj.munot\Desktop\Codes\Execution_Fast\Jiffy\jiffy.py", line 172, in _request
    raise requests.HTTPError(resp.text)
requests.exceptions.HTTPError: "Unauthorized, Session Expired or does'nt exists"
2023-03-09 11:24:07,412:ERROR:Execution.execute:Error in Orderplacement in singleorder Orderid not generated for orderdetails : {'reftag': 903, 'price': 38.15, 'token': 46024, 'qty': 25, 'strategyname': 'test_NF', 'transactiontype': 'sell', 'exchange': 'NSEFO'}
2023-03-09 11:24:07,412:ERROR:Execution.execute:Error in Orderplacement in singleorder Orderid not generated for orderdetails : {'reftag': 903, 'price': 38.15, 'token': 46024, 'qty': 25, 'strategyname': 'test_NF', 'transactiontype': 'sell', 'exchange': 'NSEFO'}
2023-03-09 11:25:07,741:ERROR:Execution.execute:Issue in Placing Order
Traceback (most recent call last):
  File "C:\Users\niraj.munot\Desktop\Codes\Execution_Fast\Execution\execute.py", line 126, in placeorder
    orderid = self.jf.placeorder(token, segment, ordertype, transactiontype, qty, price, producttype)
  File "C:\Users\niraj.munot\Desktop\Codes\Execution_Fast\Jiffy\jiffy.py", line 123, in placeorder
    return self._request("POST", endpoints['placeorder'], body)
  File "C:\Users\niraj.munot\Desktop\Codes\Execution_Fast\Jiffy\jiffy.py", line 183, in _request
    raise e
  File "C:\Users\niraj.munot\Desktop\Codes\Execution_Fast\Jiffy\jiffy.py", line 172, in _request
    raise requests.HTTPError(resp.text)
requests.exceptions.HTTPError: "Unauthorized, Session Expired or does'nt exists"
2023-03-09 11:25:07,741:ERROR:Execution.execute:Error in Orderplacement in singleorder Orderid not generated for orderdetails : {'reftag': 904, 'price': 38.15, 'token': 46024, 'qty': 25, 'strategyname': 'test_NF', 'transactiontype': 'sell', 'exchange': 'NSEFO'}
2023-03-09 11:25:07,765:ERROR:Execution.execute:Issue in Placing Order
Traceback (most recent call last):
  File "C:\Users\niraj.munot\Desktop\Codes\Execution_Fast\Execution\execute.py", line 126, in placeorder
    orderid = self.jf.placeorder(token, segment, ordertype, transactiontype, qty, price, producttype)
  File "C:\Users\niraj.munot\Desktop\Codes\Execution_Fast\Jiffy\jiffy.py", line 123, in placeorder
    return self._request("POST", endpoints['placeorder'], body)
  File "C:\Users\niraj.munot\Desktop\Codes\Execution_Fast\Jiffy\jiffy.py", line 183, in _request
    raise e
  File "C:\Users\niraj.munot\Desktop\Codes\Execution_Fast\Jiffy\jiffy.py", line 172, in _request
    raise requests.HTTPError(resp.text)
requests.exceptions.HTTPError: "Unauthorized, Session Expired or does'nt exists"
2023-03-09 11:25:07,765:ERROR:Execution.execute:Error in Orderplacement in singleorder Orderid not generated for orderdetails : {'reftag': 904, 'price': 38.15, 'token': 46024, 'qty': 25, 'strategyname': 'test_NF', 'transactiontype': 'sell', 'exchange': 'NSEFO'}
2023-03-09 11:25:07,925:ERROR:Execution.execute:Issue in Placing Order
Traceback (most recent call last):
  File "C:\Users\niraj.munot\Desktop\Codes\Execution_Fast\Execution\execute.py", line 126, in placeorder
    orderid = self.jf.placeorder(token, segment, ordertype, transactiontype, qty, price, producttype)
  File "C:\Users\niraj.munot\Desktop\Codes\Execution_Fast\Jiffy\jiffy.py", line 123, in placeorder
    return self._request("POST", endpoints['placeorder'], body)
  File "C:\Users\niraj.munot\Desktop\Codes\Execution_Fast\Jiffy\jiffy.py", line 183, in _request
    raise e
  File "C:\Users\niraj.munot\Desktop\Codes\Execution_Fast\Jiffy\jiffy.py", line 172, in _request
    raise requests.HTTPError(resp.text)
requests.exceptions.HTTPError: "Unauthorized, Session Expired or does'nt exists"
2023-03-09 11:25:07,925:ERROR:Execution.execute:Error in Orderplacement in singleorder Orderid not generated for orderdetails : {'reftag': 904, 'price': 38.15, 'token': 46024, 'qty': 25, 'strategyname': 'test_NF', 'transactiontype': 'sell', 'exchange': 'NSEFO'}
2023-03-09 11:30:24,158:ERROR:Execution.execute:Issue in Placing Order
Traceback (most recent call last):
  File "C:\Users\niraj.munot\Desktop\Codes\Execution_Fast\Execution\execute.py", line 126, in placeorder
    orderid = self.jf.placeorder(token, segment, ordertype, transactiontype, qty, price, producttype)
  File "C:\Users\niraj.munot\Desktop\Codes\Execution_Fast\Jiffy\jiffy.py", line 123, in placeorder
    return self._request("POST", endpoints['placeorder'], body)
  File "C:\Users\niraj.munot\Desktop\Codes\Execution_Fast\Jiffy\jiffy.py", line 183, in _request
    raise e
  File "C:\Users\niraj.munot\Desktop\Codes\Execution_Fast\Jiffy\jiffy.py", line 172, in _request
    raise requests.HTTPError(resp.text)
requests.exceptions.HTTPError: "Unauthorized, Session Expired or does'nt exists"
2023-03-09 11:30:24,159:ERROR:Execution.execute:Error in Orderplacement in singleorder Orderid not generated for orderdetails : {'reftag': 905, 'price': 38.15, 'token': 46024, 'qty': 50, 'strategyname': 'test_NF', 'transactiontype': 'sell', 'exchange': 'NSEFO'}
2023-03-09 11:30:24,208:ERROR:Execution.execute:Issue in Placing Order
Traceback (most recent call last):
  File "C:\Users\niraj.munot\Desktop\Codes\Execution_Fast\Execution\execute.py", line 126, in placeorder
    orderid = self.jf.placeorder(token, segment, ordertype, transactiontype, qty, price, producttype)
  File "C:\Users\niraj.munot\Desktop\Codes\Execution_Fast\Jiffy\jiffy.py", line 123, in placeorder
    return self._request("POST", endpoints['placeorder'], body)
  File "C:\Users\niraj.munot\Desktop\Codes\Execution_Fast\Jiffy\jiffy.py", line 183, in _request
    raise e
  File "C:\Users\niraj.munot\Desktop\Codes\Execution_Fast\Jiffy\jiffy.py", line 172, in _request
    raise requests.HTTPError(resp.text)
requests.exceptions.HTTPError: "Unauthorized, Session Expired or does'nt exists"
2023-03-09 11:30:24,209:ERROR:Execution.execute:Error in Orderplacement in singleorder Orderid not generated for orderdetails : {'reftag': 905, 'price': 38.15, 'token': 46024, 'qty': 25, 'strategyname': 'test_NF', 'transactiontype': 'sell', 'exchange': 'NSEFO'}
2023-03-09 13:58:36,730:ERROR:Execution.execute:Issue in Placing Order
Traceback (most recent call last):
  File "C:\Users\niraj.munot\Desktop\Codes\Execution_Fast\Execution\execute.py", line 124, in placeorder
    segment = self.get_segment(token, orderdict['exchange'])
  File "C:\Users\niraj.munot\Desktop\Codes\Execution_Fast\Execution\execute.py", line 65, in get_segment
    return self.tokendf[(self.tokendf.index == token) & (self.tokendf['Exchange'] == exchange)].iloc[0]['Segment']
  File "C:\Users\niraj.munot\Anaconda3\envs\backtesting\lib\site-packages\pandas\core\indexing.py", line 967, in __getitem__
    return self._getitem_axis(maybe_callable, axis=axis)
  File "C:\Users\niraj.munot\Anaconda3\envs\backtesting\lib\site-packages\pandas\core\indexing.py", line 1520, in _getitem_axis
    self._validate_integer(key, axis)
  File "C:\Users\niraj.munot\Anaconda3\envs\backtesting\lib\site-packages\pandas\core\indexing.py", line 1452, in _validate_integer
    raise IndexError("single positional indexer is out-of-bounds")
IndexError: single positional indexer is out-of-bounds
2023-03-09 13:58:36,730:ERROR:Execution.execute:Issue in Placing Order
Traceback (most recent call last):
  File "C:\Users\niraj.munot\Desktop\Codes\Execution_Fast\Execution\execute.py", line 124, in placeorder
    segment = self.get_segment(token, orderdict['exchange'])
  File "C:\Users\niraj.munot\Desktop\Codes\Execution_Fast\Execution\execute.py", line 65, in get_segment
    return self.tokendf[(self.tokendf.index == token) & (self.tokendf['Exchange'] == exchange)].iloc[0]['Segment']
  File "C:\Users\niraj.munot\Anaconda3\envs\backtesting\lib\site-packages\pandas\core\indexing.py", line 967, in __getitem__
    return self._getitem_axis(maybe_callable, axis=axis)
  File "C:\Users\niraj.munot\Anaconda3\envs\backtesting\lib\site-packages\pandas\core\indexing.py", line 1520, in _getitem_axis
    self._validate_integer(key, axis)
  File "C:\Users\niraj.munot\Anaconda3\envs\backtesting\lib\site-packages\pandas\core\indexing.py", line 1452, in _validate_integer
    raise IndexError("single positional indexer is out-of-bounds")
IndexError: single positional indexer is out-of-bounds
2023-03-09 13:58:36,730:ERROR:Execution.execute:Issue in Placing Order
Traceback (most recent call last):
  File "C:\Users\niraj.munot\Desktop\Codes\Execution_Fast\Execution\execute.py", line 124, in placeorder
    segment = self.get_segment(token, orderdict['exchange'])
  File "C:\Users\niraj.munot\Desktop\Codes\Execution_Fast\Execution\execute.py", line 65, in get_segment
    return self.tokendf[(self.tokendf.index == token) & (self.tokendf['Exchange'] == exchange)].iloc[0]['Segment']
  File "C:\Users\niraj.munot\Anaconda3\envs\backtesting\lib\site-packages\pandas\core\indexing.py", line 967, in __getitem__
    return self._getitem_axis(maybe_callable, axis=axis)
  File "C:\Users\niraj.munot\Anaconda3\envs\backtesting\lib\site-packages\pandas\core\indexing.py", line 1520, in _getitem_axis
    self._validate_integer(key, axis)
  File "C:\Users\niraj.munot\Anaconda3\envs\backtesting\lib\site-packages\pandas\core\indexing.py", line 1452, in _validate_integer
    raise IndexError("single positional indexer is out-of-bounds")
IndexError: single positional indexer is out-of-bounds
2023-03-09 13:58:36,730:ERROR:Execution.execute:Error in Orderplacement in dependent_execution Orderid not generated for orderdetails : {'reftag': 907, 'price': 1.5, 'token': 46022, 'qty': 25, 'strategyname': 'test2', 'transactiontype': 'buy', 'exchange': 'None'}
2023-03-09 13:58:36,730:ERROR:Execution.execute:Error in Orderplacement in dependent_execution Orderid not generated for orderdetails : {'reftag': 907, 'price': 1.5, 'token': 46022, 'qty': 25, 'strategyname': 'test2', 'transactiontype': 'buy', 'exchange': 'None'}
2023-03-09 13:58:36,730:ERROR:Execution.execute:Error in Orderplacement in dependent_execution Orderid not generated for orderdetails : {'reftag': 907, 'price': 1.5, 'token': 46022, 'qty': 25, 'strategyname': 'test2', 'transactiontype': 'buy', 'exchange': 'None'}
2023-03-09 13:58:36,851:ERROR:Execution.execute:Issue in Placing Order
Traceback (most recent call last):
  File "C:\Users\niraj.munot\Desktop\Codes\Execution_Fast\Execution\execute.py", line 124, in placeorder
    segment = self.get_segment(token, orderdict['exchange'])
  File "C:\Users\niraj.munot\Desktop\Codes\Execution_Fast\Execution\execute.py", line 65, in get_segment
    return self.tokendf[(self.tokendf.index == token) & (self.tokendf['Exchange'] == exchange)].iloc[0]['Segment']
  File "C:\Users\niraj.munot\Anaconda3\envs\backtesting\lib\site-packages\pandas\core\indexing.py", line 967, in __getitem__
    return self._getitem_axis(maybe_callable, axis=axis)
  File "C:\Users\niraj.munot\Anaconda3\envs\backtesting\lib\site-packages\pandas\core\indexing.py", line 1520, in _getitem_axis
    self._validate_integer(key, axis)
  File "C:\Users\niraj.munot\Anaconda3\envs\backtesting\lib\site-packages\pandas\core\indexing.py", line 1452, in _validate_integer
    raise IndexError("single positional indexer is out-of-bounds")
IndexError: single positional indexer is out-of-bounds
2023-03-09 13:58:36,851:ERROR:Execution.execute:Issue in Placing Order
Traceback (most recent call last):
  File "C:\Users\niraj.munot\Desktop\Codes\Execution_Fast\Execution\execute.py", line 124, in placeorder
    segment = self.get_segment(token, orderdict['exchange'])
  File "C:\Users\niraj.munot\Desktop\Codes\Execution_Fast\Execution\execute.py", line 65, in get_segment
    return self.tokendf[(self.tokendf.index == token) & (self.tokendf['Exchange'] == exchange)].iloc[0]['Segment']
  File "C:\Users\niraj.munot\Anaconda3\envs\backtesting\lib\site-packages\pandas\core\indexing.py", line 967, in __getitem__
    return self._getitem_axis(maybe_callable, axis=axis)
  File "C:\Users\niraj.munot\Anaconda3\envs\backtesting\lib\site-packages\pandas\core\indexing.py", line 1520, in _getitem_axis
    self._validate_integer(key, axis)
  File "C:\Users\niraj.munot\Anaconda3\envs\backtesting\lib\site-packages\pandas\core\indexing.py", line 1452, in _validate_integer
    raise IndexError("single positional indexer is out-of-bounds")
IndexError: single positional indexer is out-of-bounds
2023-03-09 13:58:36,851:ERROR:Execution.execute:Issue in Placing Order
Traceback (most recent call last):
  File "C:\Users\niraj.munot\Desktop\Codes\Execution_Fast\Execution\execute.py", line 124, in placeorder
    segment = self.get_segment(token, orderdict['exchange'])
  File "C:\Users\niraj.munot\Desktop\Codes\Execution_Fast\Execution\execute.py", line 65, in get_segment
    return self.tokendf[(self.tokendf.index == token) & (self.tokendf['Exchange'] == exchange)].iloc[0]['Segment']
  File "C:\Users\niraj.munot\Anaconda3\envs\backtesting\lib\site-packages\pandas\core\indexing.py", line 967, in __getitem__
    return self._getitem_axis(maybe_callable, axis=axis)
  File "C:\Users\niraj.munot\Anaconda3\envs\backtesting\lib\site-packages\pandas\core\indexing.py", line 1520, in _getitem_axis
    self._validate_integer(key, axis)
  File "C:\Users\niraj.munot\Anaconda3\envs\backtesting\lib\site-packages\pandas\core\indexing.py", line 1452, in _validate_integer
    raise IndexError("single positional indexer is out-of-bounds")
IndexError: single positional indexer is out-of-bounds
2023-03-09 13:58:36,851:ERROR:Execution.execute:Error in Orderplacement in dependent_execution Orderid not generated for orderdetails : {'reftag': 908, 'price': 2.15, 'token': 46009, 'qty': 25, 'strategyname': 'test2', 'transactiontype': 'buy', 'exchange': 'None'}
2023-03-09 13:58:36,851:ERROR:Execution.execute:Error in Orderplacement in dependent_execution Orderid not generated for orderdetails : {'reftag': 908, 'price': 2.15, 'token': 46009, 'qty': 25, 'strategyname': 'test2', 'transactiontype': 'buy', 'exchange': 'None'}
2023-03-09 13:58:36,851:ERROR:Execution.execute:Error in Orderplacement in dependent_execution Orderid not generated for orderdetails : {'reftag': 908, 'price': 2.15, 'token': 46009, 'qty': 25, 'strategyname': 'test2', 'transactiontype': 'buy', 'exchange': 'None'}
